Workbook

Sheet Listas
A1: Estado | B1: Descripción | D1: Prioridades
A2: Por hacer | B2: No iniciado. En Backlog
A3: En análisis Funcional | B3: En análisis y/o diseño
A4: En análisis Técnico | B4: En análisis y/o diseño
A5: En desarrollo | B5: En construcción
A6: QA | B6: En pruebas finales de sistemas
A7: UAT | B7: En prueba de usuario
A8: Para implementar | B8: En instalación en el ambiente de producción
A9: Cerrado | B9: Cuando el requerimiento se encuentra instalado
A10: Cancelado | B10: Cuando el requerimiento se descarta. Puede estar en cualquier estado existente.
A11: Suspendido | B11: Cuando el requerimiento se encuentra en los estados "En análisis", "En desarrollo", En Testing", "UAT" o "Para implementar".
A12: Implementado / Soporte | B12: Cuando se encuentra Implementado pero no cerrado.
A13: Validar estado | B13: Puede ser que se haya implemantado. Hay que validar si se solucionó
... A17: Planificado | B17: Ticket Planificado

Sheet Jira Exportar Excel CSV (OLD)
A1: Tipo | B1: Clave | D1: Fecha solicitado | E1: Fecha finalizado | F1: Tarea princ | G1: Resumen | H1: Cliente | I1: Componente | J1: Asignada | K1: Area | L1: Informador | M1: Prioridad | N1: Estado | O1: Sprint | P1: Fecha comprometida | Q1: Comentario | R1: Descripción
A2: Tarea | B2: MAN-2 | C2: =VALUE(RIGHT(B2,LEN(B2)-4)) -> 2 | D2: 45649 | E2: 45663 | G2: RN SAA MAN-10283. Reporte histórico de premios mayores | H2: Rio Negro | I2: SAA | J2: Santiago Obregon | K2: SAC | L2: Maria Luz Britos | M2: Medium | N2: Finalizada | O2: Sprint 4
A3: Subtarea | B3: MAN-3 | C3: =VALUE(RIGHT(B3,LEN(B3)-4)) -> 3 | F3: MAN-2 | G3: Analisis funcional | L3: Fabiana Vallejos | M3: Medium | N3: Finalizada | O3: Sprint 4
A4: Tarea | B4: MAN-4 | C4: =VALUE(RIGHT(B4,LEN(B4)-4)) -> 4 | D4: 45649 | E4: 45672 | G4: COR LOTEMOVIL MAN-10246. Listado de reporte login de agentes | H4: Corrientes | I4: Lotemovil | J4: Santiago Obregon | K4: SAC | L4: Maria Luz Britos | M4: Medium | N4: Finalizada | O4: Sprint 4
A5: Tarea | B5: MAN-5 | C5: =VALUE(RIGHT(B5,LEN(B5)-4)) -> 5 | D5: 45649 | E5: 45722 | G5: TDF SAA MAN-9935-Sprint 2 Validar fecha en carga de extracto por archivo | H5: Tierra del Fuego | I5: SAA | J5: Claudia Saissac | K5: SAP | L5: Maria Luz Britos | M5: Medium | N5: Finalizada | O5: Sprint 4
A6: Tarea | B6: MAN-6 | C6: =VALUE(RIGHT(B6,LEN(B6)-4)) -> 6 | D6: 45649 | E6: 45687 | G6: SLA SAA MAN-10330 - Sprint 4 - Modificar cáculo de Total Neto en M5/M9 de Sunmi | H6: Salta | I6: SAA | J6: Claudia Saissac | K6: SAP | L6: Maria Luz Britos | M6: Medium | N6: Finalizada | O6: Sprint 4 | R6: Solo debe restarse lo recaudado por medios digitales para que el total neto coincida con el físico
A7: Tarea | B7: MAN-7 | C7: =VALUE(RIGHT(B7,LEN(B7)-4)) -> 7 | D7: 45649 | G7: RN SAA MAN-9325 Patagonia Telebingo- Modificar forma de seleccion de cupon | H7: Rio Negro | I7: SAA | J7: leandro guadagno | K7: Sistemas | L7: Maria Luz Britos | M7: Medium | N7: Finalizada | O7: Sprint 4 | R7: En procesos de pruebas. Pidieron ellos para que se pueda seleccionar el carton por nro de recupero
A8: Tarea | B8: MAN-8 | C8: =VALUE(RIGHT(B8,LEN(B8)-4)) -> 8 | D8: 45649 | E8: 45687 | G8: MAN-10263-Se solicita quitar el mail tecnoaccion@tecnoaccion.com.ar de la pagina de tecnoaccion.com.ar y se lo reemplace con un formulario de contacto | H8: Interno | I8: Web tecno | J8: leandro guadagno | K8: Sistemas | L8: Maria Luz Britos | M8: Medium | N8: Finalizada | O8: Sprint 4
A9: Tarea | B9: MAN-9 | C9: =VALUE(RIGHT(B9,LEN(B9)-4)) -> 9 | D9: 45649 | E9: 45663 | G9: PMP SIGA MAN-9881-Sprint 3 Incorporación de los premios de Telekino en formato pre - impreso | H9: La Pampa | I9: Siga | J9: Santiago Obregon | K9: SAC | L9: Maria Luz Britos | M9: Medium | N9: Finalizada | O9: Sprint 4 | R9: Necesita validar y luego realizar pruebas
A10: Tarea | B10: MAN-10 | C10: =VALUE(RIGHT(B10,LEN(B10)-4)) -> 10 | D10: 45649 | E10: 45659 | G10: MAN-9854-Sprint 2 - Templates de facturación manualmente en Netsuite y reportes en excel con detalle de las recaudaciones que toma FABI para facturar | H10: Interno | I10: FABI | J10: Maria Luz Britos | K10: Sistemas | L10: Maria Luz Britos | M10: Medium | N10: Finalizada | O10: Sprint 4
A11: Subtarea | B11: MAN-11 | C11: =VALUE(RIGHT(B11,LEN(B11)-4)) -> 11 | F11: MAN-4 | G11: Analisis y Seguimiento. COR LOTEMOVIL. Listado de reporte login de agentes | J11: leandro guadagno | L11: leandro guadagno | M11: Medium | N11: Finalizada | O11: Sprint 4 | R11: Analisis y Seguimiento. COR LOTEMOVIL. Listado de reporte login de agentes
A12: Tarea | B12: MAN-12 | C12: =VALUE(RIGHT(B12,LEN(B12)-4)) -> 12 | D12: 45649 | E12: 45674 | G12: SC SIGA MAN-10342. Implementar pago premios con retención en agencias | H12: Santa Cruz | I12: Siga | J12: leandro guadagno | K12: Sistemas | L12: Maria Luz Britos | M12: Medium | N12: Finalizada | O12: Sprint 5
A13: Tarea | B13: MAN-13 | C13: =VALUE(RIGHT(B13,LEN(B13)-4)) -> 13 | D13: 45649 | E13: 45684 | G13: SDE SIGA MAN-10288. Carga de extractos sorteos de lotería santiagueña | H13: Sgo del Estero | I13: Siga | J13: Hector Gabaldo | K13: Sistemas | L13: Maria Luz Britos | M13: Medium | N13: Finalizada | O13: Sprint 5 | R13: Plantilla de siga. Se realizó corrección . Se espera validación del cliente y confirmación de SAC.
A14: Tarea | B14: MAN-14 | C14: =VALUE(RIGHT(B14,LEN(B14)-4)) -> 14 | D14: 45649 | E14: 45677 | G14: NQN MAN-10245-PROGRAMA PREMIOS FIN DE FIESTAS 2025 | H14: Neuquen | I14: Speta | J14: Santiago Obregon | K14: SAC | L14: Maria Luz Britos | M14: Medium | N14: Finalizada | O14: Sprint 5 | R14: PROVINCIA Neuquén APLICACIÓN Speta DESCRIPCIÓN Se requiere programar los valores para la adjudicación del sorteo de fin de fiestas en Speta. Sorteo : 2570 Fecha de sorteo : 18/01/2025 5 partes de $1.000 Importe mínimo : $ 1.000 Importe máximo : $ 5.000 IMPACTO El impacto es alto , premiación del sorteo especial de fin de fiestas. DETALLES DE DESPLIEGUE Implica la actualización de las tablas de la base de datos del Speta : Tabla : lote.lo_programa_de_premios Para n_progra = 7 Campo : i_minimo = 1000 Campo : i_maximo = 5000
A15: Tarea | B15: MAN-15 | C15: =VALUE(RIGHT(B15,LEN(B15)-4)) -> 15 | D15: 45649 | E15: 45670 | G15: NQN MAN-10244 PROGRAMA PREMIOS REYES 2025 | H15: Neuquen | I15: Speta | J15: Santiago Obregon | K15: SAC | L15: Maria Luz Britos | M15: Medium | N15: Finalizada | O15: Sprint 5 | R15: PROVINCIA Neuquén APLICACIÓN Speta DESCRIPCIÓN Se requiere programar los valores para la adjudicacion del sorteo de reyes en Speta. Sorteo : 2569 Fecha de sorteo : 11/01/2025 5 partes de $2.000 Importe mínimo : $ 2.000 Importe máximo : $ 10.000 IMPACTO El impacto es alto , premiación del sorteo especial de reyes. DETALLES DE DESPLIEGUE Implica la actualización de las tablas de la base de datos del Speta : Tabla : lote.lo_programa_de_premios Para n_progra = 6 Campo : i_minimo = 2000 Campo : i_maximo = 10000 FECHA SUGERIDA DE DESPLIEGUE A disponer por el área según recursos y disponibilidad. La fecha de la actualización deberá ser anterior a la fecha del sorteo : 11 de Enero de 2025.
A16: Tarea | B16: MAN-16 | C16: =VALUE(RIGHT(B16,LEN(B16)-4)) -> 16 | D16: 45649 | E16: 45680 | G16: SLA LOTLINE MAN-10336. Activar solicitud ingreso de CUIL a usuarios | H16: Salta | I16: Lotline | J16: leandro guadagno | K16: Sistemas | L16: Maria Luz Britos | M16: Medium | N16: Finalizada | Q16: Sale de mantenimiento y pasa a proyecto
A17: Tarea | B17: MAN-17 | C17: =VALUE(RIGHT(B17,LEN(B17)-4)) -> 17 | D17: 45649 | E17: 45649 | G17: SLA LOTLINE MAN-10146- Sprint 5 - Agregar en página Lotline opción de descarga de la aplicación. | H17: Salta | I17: Lotline | J17: leandro guadagno | K17: Sistemas | L17: Maria Luz Britos | M17: Medium | N17: Finalizada | Q17: Sale de mantenimiento y pasa a proyecto
A18: Tarea | B18: MAN-18 | C18: =VALUE(RIGHT(B18,LEN(B18)-4)) -> 18 | D18: 45649 | E18: 45693 | G18: COR NOGA MAN-10139. Agregar columna con nombre de juego | H18: Corrientes | I18: Noga | J18: leandro guadagno | K18: Sistemas | L18: Maria Luz Britos | M18: Medium | N18: Finalizada | O18: Sprint 6
A19: Subtarea | B19: MAN-19 | C19: =VALUE(RIGHT(B19,LEN(B19)-4)) -> 19 | F19: MAN-7 | G19: Analisis, Seguimiento y prueba. | J19: leandro guadagno | L19: leandro guadagno | M19: Medium | N19: Finalizada | O19: Sprint 4 | R19: Analisis, Seguimiento y prueba.
A20: Tarea | B20: MAN-20 | C20: =VALUE(RIGHT(B20,LEN(B20)-4)) -> 20 | D20: 45649 | E20: 45653 | G20: PMP MAN-10345 SGC carga de ejercicio 2025 | H20: La Pampa | I20: SCG | J20: Hector Gabaldo | K20: Sistemas | L20: Maria Luz Britos | M20: Medium | N20: Finalizada | O20: Sprint 5 | R20: No aparece el ejercicio nuevo 2025. Todos los años se carga un ejercicio nuevo para SGC . Se crea Ejercicio nuevo y periodo.
A21: Subtarea | B21: MAN-21 | C21: =VALUE(RIGHT(B21,LEN(B21)-4)) -> 21 | F21: MAN-8 | G21: Análisis funcional. Modificación en Página Tecnoacción. | J21: leandro guadagno | L21: Claudia Saissac | M21: Medium | N21: Finalizada | O21: Sprint 4 | R21: Análisis funcional. Modificación en Página Tecnoacción.
A22: Subtarea | B22: MAN-22 | C22: =VALUE(RIGHT(B22,LEN(B22)-4)) -> 22 | F22: MAN-12 | G22: Analisis y Seguimiento. SC SIGA. Implementar pago premios con retención en agencias | J22: leandro guadagno | L22: leandro guadagno | M22: Medium | N22: Finalizada | O22: Sprint 5 | R22: Analisis y Seguimiento. SC SIGA. Implementar pago premios con retención en agencias
A23: Subtarea | B23: MAN-23 | C23: =VALUE(RIGHT(B23,LEN(B23)-4)) -> 23 | F23: MAN-14 | G23: Implementar | L23: Maria Luz Britos | M23: Medium | N23: Finalizada | O23: Sprint 5
A24: Subtarea | B24: MAN-24 | C24: =VALUE(RIGHT(B24,LEN(B24)-4)) -> 24 | F24: MAN-5 | G24: Analisis funcional | J24: Hector Gabaldo | L24: Maria Luz Britos | M24: Medium | N24: Finalizada | O24: Sprint 4
A25: Tarea | B25: MAN-25 | C25: =VALUE(RIGHT(B25,LEN(B25)-4)) -> 25 | D25: 45652 | E25: 45672 | G25: SC SIGA. Retenciones de sorteos extaordinarios unificada | H25: Santa Cruz | I25: Siga | J25: Santiago Obregon | K25: SAC | L25: Santiago Obregon | M25: Medium | N25: Finalizada | O25: Sprint 5 | R25: Lotería de Santa Cruz solicita no aplicar retenciones a los premios que recuperan el valor del entero al igual que se hizo en Neuquén y Rio Negro
A26: Tarea | B26: MAN-26 | C26: =VALUE(RIGHT(B26,LEN(B26)-4)) -> 26 | D26: 45652 | G26: NQN LOTLINE. Análisis por bug en carga de stock de lotería | H26: Neuquen | I26: Lotline | J26: leandro guadagno | K26: Sistemas | L26: Maria Luz Britos | M26: Medium | N26: Por hacer | R26: A partir de un pedido de C.Lopez de tener todos los juegos disponibles para jugar en la plataforma Lotline se encontró un error que no trae billetes de "Lotería". El bug se encontró en el "appService" que no soporta letras en el stock cargado. A.Iribarren estuvo y está trabajando desde principio de la semana del 09/12. Ambiente de prueba: http://humberto.tecnoaccion.com.ar:8080/feweb206LOTLINENQNFULL https://testnqn.tecnoaccion.com.ar.
A27: Subtarea | B27: MAN-27 | C27: =VALUE(RIGHT(B27,LEN(B27)-4)) -> 27 | F27: MAN-26 | G27: Analisis y Seguimiento. APPService - Análisis por bug en carga de stock de lotería. | J27: leandro guadagno | L27: Maria Luz Britos | M27: Medium | N27: En curso | R27: *Analisis y Seguimiento. APPService - Análisis por bug en carga de stock de lotería*
A28: Subtarea | B28: MAN-28 | C28: =VALUE(RIGHT(B28,LEN(B28)-4)) -> 28 | F28: MAN-26 | G28: Análisis y Desarrollo por bug en carga de stock de lotería. | J28: Alexis Gutierrez | L28: Maria Luz Britos | M28: Medium | N28: Por hacer | R28: A partir de un pedido de C.Lopez de tener todos los juegos disponibles para jugar en la plataforma Lotline se encontró un error que no trae billetes de "Lotería". El bug se encontró en el "appService" que no soporta letras en el stock cargado. A.Iribarren estuvo y está trabajando desde principio de la semana del 09/12. Ambiente de prueba: http://humberto.tecnoaccion.com.ar:8080/feweb206LOTLINENQNFULL https://testnqn.tecnoaccion.com.ar.
A29: Tarea | B29: MAN-29 | C29: =VALUE(RIGHT(B29,LEN(B29)-4)) -> 29 | D29: 45652 | G29: SLA PREJUEGO. Trackeo de boton compartir de Whatsapp. | H29: Salta | I29: Prejuego | L29: Santiago Obregon | M29: Medium | N29: Finalizada | R29: Salta solicita incorporar el trackeo del botón compartir de whatsapp en plataforma Prejuego.
A30: Subtarea | B30: MAN-30 | C30: =VALUE(RIGHT(B30,LEN(B30)-4)) -> 30 | F30: MAN-25 | G30: Prueba e implementación | J30: Claudia Saissac | L30: hector Gabaldo | M30: Medium | N30: Finalizada | O30: Sprint 5 | R30: JIRA https://tecnoproyectos.atlassian.net/browse/MAN-25 SUBTAREA https://tecnoproyectos.atlassian.net/browse/MAN-30 PROVINCIA Santa Cruz APLICACIÓN Base de datos Oracle Santa Cruz. DESCRIPCIÓN Actualizar versión de base de datos SAA productivas de : Versión 78_04 a la 78_05. IMPACTO El impacto es alto, a fin de actualizar base de datos para modificar la forma del calculo de retenciones en Front-end y Siga. Provincia de Santa Cruz. DETALLES Coordinar actualización con el área de infraestructura. FECHA SUGERIDA DE DESPLIEGUE A disponer por el área según recursos y disponibilidad. La fecha de la actualización deberá ser anterior al Sábado 04/01/2025.
A31: Tarea | B31: MAN-31 | C31: =VALUE(RIGHT(B31,LEN(B31)-4)) -> 31 | D31: 45652 | E31: 45693 | G31: COR SAA. No salen los importes de cupones a caducar en consulta de TJ. | H31: Corrientes | I31: SAA | J31: Claudia Saissac | K31: SAP | L31: Santiago Obregon | M31: Medium | N31: Finalizada | R31: En el ticket de la consulta Premios a caducar en agencia de TJ no salen los importes de los cupones a caducar.
A32: Tarea | B32: MAN-32 | C32: =VALUE(RIGHT(B32,LEN(B32)-4)) -> 32 | D32: 45652 | E32: 45656 | G32: NQN SGC. Cargar nuevo ejercicio 2025 | H32: Neuquen | I32: SCG | J32: Hector Gabaldo | K32: Sistemas | L32: Santiago Obregon | M32: Medium | N32: Finalizada | R32: La contadora Adriana Durazzi del IJAN solicita la creación del ejercicio contable 2025 en SGC con exportación del plan de cuentas del 2024.
A33: Subtarea | B33: MAN-33 | C33: =VALUE(RIGHT(B33,LEN(B33)-4)) -> 33 | F33: MAN-6 | G33: Analisis funcional | J33: Maria Luz Britos | L33: Maria Luz Britos | M33: Medium | N33: Finalizada | O33: Sprint 4
A34: Subtarea | B34: MAN-34 | C34: =VALUE(RIGHT(B34,LEN(B34)-4)) -> 34 | F34: MAN-25 | G34: Prueba e implementación | J34: Claudia Saissac | L34: hector Gabaldo | M34: Medium | N34: Finalizada | O34: Sprint 5 | R34: JIRA https://tecnoproyectos.atlassian.net/browse/MAN-25 SUBTAREA https://tecnoproyectos.atlassian.net/browse/MAN-34 PROVINCIA Santa Cruz APLICACIÓN Siga DESCRIPCIÓN Se requiere actualizar SP de la aplicación Siga Santa Cruz para contemplar cambios funcionales de premiación de sorteos extraordinarios IMPACTO El impacto es alto, a fin de actualizar Siga para modificar la forma del calculo de retenciones. Provincias de Santa Cruz. DETALLES Coordinar actualización con Ricardo Tejerina. FECHA SUGERIDA DE DESPLIEGUE A disponer por el área según recursos y disponibilidad. La fecha de la actualización deberá ser anterior al Sábado 04/01.
A35: Subtarea | B35: MAN-35 | C35: =VALUE(RIGHT(B35,LEN(B35)-4)) -> 35 | F35: MAN-18 | G35: Analisis funcional. MAN-10139-COR NOGA. Agregar columna con nombre de juego | J35: leandro guadagno | L35: hector Gabaldo | M35: Medium | N35: Finalizada | O35: Sprint 6 | R35: Analisis funcional. MAN-10139-COR NOGA. Agregar columna con nombre de juego
A36: Tarea | B36: MAN-36 | C36: =VALUE(RIGHT(B36,LEN(B36)-4)) -> 36 | D36: 45653 | E36: 45653 | G36: TDF LOTEMOVIL. Extracto Santa Fe se visualiza 2 veces | H36: Tierra del Fuego | I36: Lotemovil | L36: Santiago Obregon | M36: Medium | N36: Finalizada | R36: El extracto de Santa Fe se muestra duplicado en resultados quiniela de Lotemóvil.
A37: Error | B37: MAN-37 | C37: =VALUE(RIGHT(B37,LEN(B37)-4)) -> 37 | D37: 45653 | E37: 45686 | G37: SDE SAA. Selección de listado minuta CC da error agregando agencia 1035. | H37: Sgo del Estero | I37: SAA | J37: Maria Luz Britos | K37: Sistemas | L37: Santiago Obregon | M37: Medium | N37: Finalizada | R37: Buen día. El departamento de Sistemas solicita que se revisen los filtros de Agencias en la Minuta de Cuenta Corriente. Puntualmente el error ocurre cuando se lista hasta la Agencia 1035. No así cuando se lista hasta la Agencia 1033 o se lista solamente a la Agencia 1035.
A38: Tarea | B38: MAN-38 | C38: =VALUE(RIGHT(B38,LEN(B38)-4)) -> 38 | D38: 45653 | E38: 45665 | G38: NQN SIGA. Carga premios especiales unificada año nuevo. | H38: Neuquen | I38: Siga | J38: Claudia Saissac | K38: SAP | L38: Santiago Obregon | M38: Medium | N38: Finalizada | R38: Se solicita la carga de los premios especiales de la unificada de año nuevo de fecha 04/01/2025.
A39: Subtarea | B39: MAN-39 | C39: =VALUE(RIGHT(B39,LEN(B39)-4)) -> 39 | F39: MAN-10 | G39: Analisis funcional | J39: Maria Luz Britos | L39: Maria Luz Britos | M39: Medium | N39: Finalizada | O39: Sprint 4
A40: Subtarea | B40: MAN-40 | C40: =VALUE(RIGHT(B40,LEN(B40)-4)) -> 40 | F40: MAN-10 | G40: Prueba e implementación | J40: Claudia Saissac | L40: Maria Luz Britos | M40: Medium | N40: Finalizada | O40: Sprint 4
...

Sheet Hoja1
A3: Suma de Desarrollo | B3: Estado
A4: Evaluación real del caso | B4: A estimar | C4: A planificar | D4: A priorizar | E4: Para implementar | F4: Validar estado | G4: En desarrollo | H4: Planificado | I4: QA | J4: Total general
A5: Consulta | D5: 0 | J5: 0
A6: Mantenimiento correctivo | C6: 287 | D6: 476 | F6: 32 | H6: 304 | I6: 0 | J6: 1099
A7: Mantenimiento evolutivo | B7: 40 | C7: 899 | D7: 2280 | F7: 0 | G7: 1268 | I7: 0 | J7: 4487
A8: Mantenimiento preventivo | C8: 28 | D8: 36 | G8: 0 | J8: 64
A9: Total general | B9: 40 | C9: 1214 | D9: 2792 | F9: 32 | G9: 1268 | H9: 304 | I9: 0 | J9: 5650

Sheet Backlog
A1: Clave del caso | B1: Evaluación real del caso | C1: Prioridad real | D1: Fecha alta de la solicitud | E1: Título o Asunto | F1: Descripción detallada y completa del caso | G1: Cliente que solicita | H1: Componente | I1: Area responsable de traccionar | J1: OP | K1: Estado | L1: Fecha Requerida en Producción | M1: Fecha comprometida (para UAT) | N1: Fecha Real de Cierre | O1: Comentarios Funcionales | P1: Comentarios Técnicos | Q1: Referencia al documento | R1: Análisis | S1: Estimación Desarrollo | T1: Desarrollo Realidad | U1: QA/UAT | V1: Implementación | W1: Total | X1: Visto | Y1: Columna3 | Z1: Columna4 | AA1: Fase | AB1: Dias_abiertos | AC1: En_plazo | AJ1: Comentarios SAC
A2: 16613 | B2: Mantenimiento correctivo | C2: Muy alta | D2: 46142 | E2: CNQ-GAMMA-GAMMA-DIFERENCIA CALCULO CSA | F2: EL calculo de CSA tiene diferencias debido a que no esta calculando para todas las maquinas de un PDV motivo: Gamma no actualiza las maquinas activas y habilitadas en los PDV al momento de hacer los cálculos de CSA, tomando solo los datos que ya tenia grabados antes de la nueva implementación del día 6/04/2026. Este problema tambien afecta al cobro de CSA en SALTA | H2: Gamma | K2: Para implementar | AA2: =_xlfn.XLOOKUP(Backlog[[#This Row],[Estado]],CatEstados[Estado],CatEstados[Fase],"Otro") -> Implementación | AB2: =IF(OR(ISBLANK(Backlog[[#This Row],[Fecha comprometida (para UAT)]]),Backlog[[#This Row],[Fecha comprometida (para UAT)]]=""), "Sin fecha comprometida", IF( Backlog[[#This Row],[Fecha Real de Cierre]]="", TODAY()-Backlog[[#This Row],[Fecha comprometida (para UAT)]], Backlog[[#This Row],[Fecha Real de Cierre]]-Backlog[[#This Row],[Fecha comprometida (para UAT)]] ) ) -> Sin fecha comprometida | AC2: =IF(OR(#REF!="",NOT(ISNUMBER(Backlog[[#This Row],[Dias_abiertos]]))),"",IF(Backlog[[#This Row],[Dias_abiertos]]<=7,"En plazo",IFERROR(IF(Backlog[[#This Row],[Dias_abiertos]]=_xlfn.XLOOKUP(TRIM(#REF!),CatSLA[Prioridad],CatSLA[SLA_dias],""),"En plazo","Fuera de plazo"),"Sin SLA"))) -> #REF!
A3: GAMMA-817 SF16721 | B3: Mantenimiento correctivo | C3: Muy alta | D3: 46149 | E3: End-point de adjudicaciones | F3: Se necesita la incorporación del campo fechaTotPremios en la respuesta del end-point de adjudicaciones para la Provincia de La Pampa. Se detecto en esta provincia el faltante de este campo lo que no permite realizar la liquidaciones a sorteo cerrado con premios. | G3: La Pampa | H3: Saaservice | I3: Mantenimiento | K3: Planificado | AA3: =_xlfn.XLOOKUP(Backlog[[#This Row],[Estado]],CatEstados[Estado],CatEstados[Fase],"Otro") -> Por hacer | AB3: =IF(OR(ISBLANK(Backlog[[#This Row],[Fecha comprometida (para UAT)]]),Backlog[[#This Row],[Fecha comprometida (para UAT)]]=""), "Sin fecha comprometida", IF( Backlog[[#This Row],[Fecha Real de Cierre]]="", TODAY()-Backlog[[#This Row],[Fecha comprometida (para UAT)]], Backlog[[#This Row],[Fecha Real de Cierre]]-Backlog[[#This Row],[Fecha comprometida (para UAT)]] ) ) -> Sin fecha comprometida | AC3: =IF(OR(#REF!="",NOT(ISNUMBER(Backlog[[#This Row],[Dias_abiertos]]))),"",IF(Backlog[[#This Row],[Dias_abiertos]]<=7,"En plazo",IFERROR(IF(Backlog[[#This Row],[Dias_abiertos]]=_xlfn.XLOOKUP(TRIM(#REF!),CatSLA[Prioridad],CatSLA[SLA_dias],""),"En plazo","Fuera de plazo"),"Sin SLA"))) -> #REF!
A4: GAMMA-746 SF16529 | B4: Mantenimiento preventivo | C4: Alta | D4: 46140 | E4: Se necesita eliminar el servicio Extract | F4: Servicio Extract: Servicio en desuso que se utilizaba para buscar datos en sistemas externos a gamma. Se necesita Eliminar el servicio. | H4: Gamma | K4: A planificar | AA4: =_xlfn.XLOOKUP(Backlog[[#This Row],[Estado]],CatEstados[Estado],CatEstados[Fase],"Otro") -> Por hacer | AB4: =IF(OR(ISBLANK(Backlog[[#This Row],[Fecha comprometida (para UAT)]]),Backlog[[#This Row],[Fecha comprometida (para UAT)]]=""), "Sin fecha comprometida", IF( Backlog[[#This Row],[Fecha Real de Cierre]]="", TODAY()-Backlog[[#This Row],[Fecha comprometida (para UAT)]], Backlog[[#This Row],[Fecha Real de Cierre]]-Backlog[[#This Row],[Fecha comprometida (para UAT)]] ) ) -> Sin fecha comprometida | AC4: =IF(OR(#REF!="",NOT(ISNUMBER(Backlog[[#This Row],[Dias_abiertos]]))),"",IF(Backlog[[#This Row],[Dias_abiertos]]<=7,"En plazo",IFERROR(IF(Backlog[[#This Row],[Dias_abiertos]]=_xlfn.XLOOKUP(TRIM(#REF!),CatSLA[Prioridad],CatSLA[SLA_dias],""),"En plazo","Fuera de plazo"),"Sin SLA"))) -> #REF!
A5: GAMMA-747 SF16530 | B5: Mantenimiento preventivo | C5: Alta | D5: 46140 | E5: Se necesita Depurar la BD Extract | F5: BD Extract Bd relacionada con servicio Extract y las configuraciones necesarias para lo que se procesaba Se necesita Depurar la BD Tablas con información de procesos executions Borrar todos los registros movement_executions_status Borrar todos los registros | H5: Gamma | K5: A planificar | AA5: =_xlfn.XLOOKUP(Backlog[[#This Row],[Estado]],CatEstados[Estado],CatEstados[Fase],"Otro") -> Por hacer | AB5: =IF(OR(ISBLANK(Backlog[[#This Row],[Fecha comprometida (para UAT)]]),Backlog[[#This Row],[Fecha comprometida (para UAT)]]=""), "Sin fecha comprometida", IF( Backlog[[#This Row],[Fecha Real de Cierre]]="", TODAY()-Backlog[[#This Row],[Fecha comprometida (para UAT)]], Backlog[[#This Row],[Fecha Real de Cierre]]-Backlog[[#This Row],[Fecha comprometida (para UAT)]] ) ) -> Sin fecha comprometida | AC5: =IF(OR(#REF!="",NOT(ISNUMBER(Backlog[[#This Row],[Dias_abiertos]]))),"",IF(Backlog[[#This Row],[Dias_abiertos]]<=7,"En plazo",IFERROR(IF(Backlog[[#This Row],[Dias_abiertos]]=_xlfn.XLOOKUP(TRIM(#REF!),CatSLA[Prioridad],CatSLA[SLA_dias],""),"En plazo","Fuera de plazo"),"Sin SLA"))) -> #REF!
A6: GAMMA-748 SF16531 | B6: Mantenimiento preventivo | C6: Alta | D6: 46140 | E6: Se necesita Eliminar el servicio Transform | F6: Descripción Servicio Transform servicio en desuso que se utilizaba para procesar la información extraída por "Extract" Se necesita Eliminar el servicio. | H6: Gamma | K6: A planificar | AA6: =_xlfn.XLOOKUP(Backlog[[#This Row],[Estado]],CatEstados[Estado],CatEstados[Fase],"Otro") -> Por hacer | AB6: =IF(OR(ISBLANK(Backlog[[#This Row],[Fecha comprometida (para UAT)]]),Backlog[[#This Row],[Fecha comprometida (para UAT)]]=""), "Sin fecha comprometida", IF( Backlog[[#This Row],[Fecha Real de Cierre]]="", TODAY()-Backlog[[#This Row],[Fecha comprometida (para UAT)]], Backlog[[#This Row],[Fecha Real de Cierre]]-Backlog[[#This Row],[Fecha comprometida (para UAT)]] ) ) -> Sin fecha comprometida | AC6: =IF(OR(#REF!="",NOT(ISNUMBER(Backlog[[#This Row],[Dias_abiertos]]))),"",IF(Backlog[[#This Row],[Dias_abiertos]]<=7,"En plazo",IFERROR(IF(Backlog[[#This Row],[Dias_abiertos]]=_xlfn.XLOOKUP(TRIM(#REF!),CatSLA[Prioridad],CatSLA[SLA_dias],""),"En plazo","Fuera de plazo"),"Sin SLA"))) -> #REF!
A7: GAMMA-749 SF16532 | B7: Mantenimiento preventivo | C7: Alta | D7: 46140 | E7: Se necesita Depurar la BD Transform | F7: Descripción BD Transform BD relacionada con el servicio Transform Se necesita Depurar la BD Tablas con información del proceso no hay datos | H7: Gamma | K7: A planificar | AA7: =_xlfn.XLOOKUP(Backlog[[#This Row],[Estado]],CatEstados[Estado],CatEstados[Fase],"Otro") -> Por hacer | AB7: =IF(OR(ISBLANK(Backlog[[#This Row],[Fecha comprometida (para UAT)]]),Backlog[[#This Row],[Fecha comprometida (para UAT)]]=""), "Sin fecha comprometida", IF( Backlog[[#This Row],[Fecha Real de Cierre]]="", TODAY()-Backlog[[#This Row],[Fecha comprometida (para UAT)]], Backlog[[#This Row],[Fecha Real de Cierre]]-Backlog[[#This Row],[Fecha comprometida (para UAT)]] ) ) -> Sin fecha comprometida | AC7: =IF(OR(#REF!="",NOT(ISNUMBER(Backlog[[#This Row],[Dias_abiertos]]))),"",IF(Backlog[[#This Row],[Dias_abiertos]]<=7,"En plazo",IFERROR(IF(Backlog[[#This Row],[Dias_abiertos]]=_xlfn.XLOOKUP(TRIM(#REF!),CatSLA[Prioridad],CatSLA[SLA_dias],""),"En plazo","Fuera de plazo"),"Sin SLA"))) -> #REF!
A8: GAMMA-750 SF16533 | B8: Mantenimiento preventivo | C8: Alta | D8: 46140 | E8: Se necesita Eliminar el servicio Load | F8: Servicio Load servicio que se utilizaba para homologar(guardar) la información generada por "Transform" y otros servicios Se necesita Eliminar el servicio. | H8: Gamma | K8: A planificar | AA8: =_xlfn.XLOOKUP(Backlog[[#This Row],[Estado]],CatEstados[Estado],CatEstados[Fase],"Otro") -> Por hacer | AB8: =IF(OR(ISBLANK(Backlog[[#This Row],[Fecha comprometida (para UAT)]]),Backlog[[#This Row],[Fecha comprometida (para UAT)]]=""), "Sin fecha comprometida", IF( Backlog[[#This Row],[Fecha Real de Cierre]]="", TODAY()-Backlog[[#This Row],[Fecha comprometida (para UAT)]], Backlog[[#This Row],[Fecha Real de Cierre]]-Backlog[[#This Row],[Fecha comprometida (para UAT)]] ) ) -> Sin fecha comprometida | AC8: =IF(OR(#REF!="",NOT(ISNUMBER(Backlog[[#This Row],[Dias_abiertos]]))),"",IF(Backlog[[#This Row],[Dias_abiertos]]<=7,"En plazo",IFERROR(IF(Backlog[[#This Row],[Dias_abiertos]]=_xlfn.XLOOKUP(TRIM(#REF!),CatSLA[Prioridad],CatSLA[SLA_dias],""),"En plazo","Fuera de plazo"),"Sin SLA"))) -> #REF!
A9: GAMMA-751 SF16534 | B9: Mantenimiento preventivo | C9: Alta | D9: 46140 | E9: Se necesita Depurar la BD Load | F9: BD Load BD relacionada con el servicio Load Se necesita Depurar la BD Tablas con información del proceso errors Borrar todos los registros non_homologated_movements Borrar todos los registros non_homologated_raffles Borrar todos los registros raffles Borrar todos los registros success_movements Borrar todos los registros | H9: Gamma | K9: A planificar | AA9: =_xlfn.XLOOKUP(Backlog[[#This Row],[Estado]],CatEstados[Estado],CatEstados[Fase],"Otro") -> Por hacer | AB9: =IF(OR(ISBLANK(Backlog[[#This Row],[Fecha comprometida (para UAT)]]),Backlog[[#This Row],[Fecha comprometida (para UAT)]]=""), "Sin fecha comprometida", IF( Backlog[[#This Row],[Fecha Real de Cierre]]="", TODAY()-Backlog[[#This Row],[Fecha comprometida (para UAT)]], Backlog[[#This Row],[Fecha Real de Cierre]]-Backlog[[#This Row],[Fecha comprometida (para UAT)]] ) ) -> Sin fecha comprometida | AC9: =IF(OR(#REF!="",NOT(ISNUMBER(Backlog[[#This Row],[Dias_abiertos]]))),"",IF(Backlog[[#This Row],[Dias_abiertos]]<=7,"En plazo",IFERROR(IF(Backlog[[#This Row],[Dias_abiertos]]=_xlfn.XLOOKUP(TRIM(#REF!),CatSLA[Prioridad],CatSLA[SLA_dias],""),"En plazo","Fuera de plazo"),"Sin SLA"))) -> #REF!
A10: GAMMA-752 SF16535 | B10: Mantenimiento preventivo | C10: Alta | D10: 46140 | E10: Se necesita Eliminar el servicio Rulesengine | F10: Servicio Rulesengine servicio que se utilizaba para administrar y procesar las reglas de la loteria ademas de procesar informacion para las mismas Se necesita Eliminar el servicio. | H10: Gamma | K10: A planificar | AA10: =_xlfn.XLOOKUP(Backlog[[#This Row],[Estado]],CatEstados[Estado],CatEstados[Fase],"Otro") -> Por hacer | AB10: =IF(OR(ISBLANK(Backlog[[#This Row],[Fecha comprometida (para UAT)]]),Backlog[[#This Row],[Fecha comprometida (para UAT)]]=""), "Sin fecha comprometida", IF( Backlog[[#This Row],[Fecha Real de Cierre]]="", TODAY()-Backlog[[#This Row],[Fecha comprometida (para UAT)]], Backlog[[#This Row],[Fecha Real de Cierre]]-Backlog[[#This Row],[Fecha comprometida (para UAT)]] ) ) -> Sin fecha comprometida | AC10: =IF(OR(#REF!="",NOT(ISNUMBER(Backlog[[#This Row],[Dias_abiertos]]))),"",IF(Backlog[[#This Row],[Dias_abiertos]]<=7,"En plazo",IFERROR(IF(Backlog[[#This Row],[Dias_abiertos]]=_xlfn.XLOOKUP(TRIM(#REF!),CatSLA[Prioridad],CatSLA[SLA_dias],""),"En plazo","Fuera de plazo"),"Sin SLA"))) -> #REF!
A11: GAMMA-753 SF16536 | B11: Mantenimiento preventivo | C11: Alta | D11: 46140 | E11: Se necesita Depurar la BD Rulesengine | F11: BD Rulesengine BD relacionada con el servicio Rulesengine Se necesita Depurar la BD Tablas con informacion del proceso adjacent_rules Borrar todos los registros execution_history Borrar todos los registros item_conditions Borrar todos los registros kafka_errors Borrar todos los registros processable_item_groups Borrar todos los registros processable_items Borrar todos los registros processed_items Borrar todos los registros processed_items_relations Borrar todos los registros rule_conditions Borrar todos los registros rule_indexes Borrar todos los registros rules Borrar todos los registros | H11: Gamma | K11: A planificar | AA11: =_xlfn.XLOOKUP(Backlog[[#This Row],[Estado]],CatEstados[Estado],CatEstados[Fase],"Otro") -> Por hacer | AB11: =IF(OR(ISBLANK(Backlog[[#This Row],[Fecha comprometida (para UAT)]]),Backlog[[#This Row],[Fecha comprometida (para UAT)]]=""), "Sin fecha comprometida", IF( Backlog[[#This Row],[Fecha Real de Cierre]]="", TODAY()-Backlog[[#This Row],[Fecha comprometida (para UAT)]], Backlog[[#This Row],[Fecha Real de Cierre]]-Backlog[[#This Row],[Fecha comprometida (para UAT)]] ) ) -> Sin fecha comprometida | AC11: =IF(OR(#REF!="",NOT(ISNUMBER(Backlog[[#This Row],[Dias_abiertos]]))),"",IF(Backlog[[#This Row],[Dias_abiertos]]<=7,"En plazo",IFERROR(IF(Backlog[[#This Row],[Dias_abiertos]]=_xlfn.XLOOKUP(TRIM(#REF!),CatSLA[Prioridad],CatSLA[SLA_dias],""),"En plazo","Fuera de plazo"),"Sin SLA"))) -> #REF!
A12: GAMMA-754 SF16537 | B12: Mantenimiento preventivo | C12: Alta | D12: 46140 | E12: Depurar BD ETL | F12: BD ETL Tablas con informacion del proceso a depurar no_homologated Borrado selectivo Registros con fecha de borrado logico borrar todos Registros sin fecha de borrado logico borrar los registros de mas de 31 dias de antiguidad procesos Borrado selectivo Borrar los registros de mas de 31 dias de antiguidad | H12: Gamma | K12: A planificar | AA12: =_xlfn.XLOOKUP(Backlog[[#This Row],[Estado]],CatEstados[Estado],CatEstados[Fase],"Otro") -> Por hacer | AB12: =IF(OR(ISBLANK(Backlog[[#This Row],[Fecha comprometida (para UAT)]]),Backlog[[#This Row],[Fecha comprometida (para UAT)]]=""), "Sin fecha comprometida", IF( Backlog[[#This Row],[Fecha Real de Cierre]]="", TODAY()-Backlog[[#This Row],[Fecha comprometida (para UAT)]], Backlog[[#This Row],[Fecha Real de Cierre]]-Backlog[[#This Row],[Fecha comprometida (para UAT)]] ) ) -> Sin fecha comprometida | AC12: =IF(OR(#REF!="",NOT(ISNUMBER(Backlog[[#This Row],[Dias_abiertos]]))),"",IF(Backlog[[#This Row],[Dias_abiertos]]<=7,"En plazo",IFERROR(IF(Backlog[[#This Row],[Dias_abiertos]]=_xlfn.XLOOKUP(TRIM(#REF!),CatSLA[Prioridad],CatSLA[SLA_dias],""),"En plazo","Fuera de plazo"),"Sin SLA"))) -> #REF!
A13: GAMMA-755 SF16538 | B13: Mantenimiento preventivo | C13: Alta | D13: 46140 | E13: Depurar BD Contability | F13: BD Contability Tablas con informacion del proceso a depurar entries Borrado selectivo Registros con fecha de borrado logico borrar todos entry_rows Borrado selectivo Registros con fecha de borrado logico borrar todos file_entries Borrado selectivo Registros con fecha de borrado logico borrar todos | H13: Gamma | K13: A planificar | AA13: =_xlfn.XLOOKUP(Backlog[[#This Row],[Estado]],CatEstados[Estado],CatEstados[Fase],"Otro") -> Por hacer | AB13: =IF(OR(ISBLANK(Backlog[[#This Row],[Fecha comprometida (para UAT)]]),Backlog[[#This Row],[Fecha comprometida (para UAT)]]=""), "Sin fecha comprometida", IF( Backlog[[#This Row],[Fecha Real de Cierre]]="", TODAY()-Backlog[[#This Row],[Fecha comprometida (para UAT)]], Backlog[[#This Row],[Fecha Real de Cierre]]-Backlog[[#This Row],[Fecha comprometida (para UAT)]] ) ) -> Sin fecha comprometida | AC13: =IF(OR(#REF!="",NOT(ISNUMBER(Backlog[[#This Row],[Dias_abiertos]]))),"",IF(Backlog[[#This Row],[Dias_abiertos]]<=7,"En plazo",IFERROR(IF(Backlog[[#This Row],[Dias_abiertos]]=_xlfn.XLOOKUP(TRIM(#REF!),CatSLA[Prioridad],CatSLA[SLA_dias],""),"En plazo","Fuera de plazo"),"Sin SLA"))) -> #REF!
A14: GAMMA-756 SF16539 | B14: Mantenimiento preventivo | C14: Alta | D14: 46140 | E14: Depurar BD Checking_account | F14: BD Checking_account Tablas con informacion del proceso a depurar agency_settlements Borrado selectivo Registros con fecha de borrado logico borrar todos execution_movements Borrar todos los registros kafka_errors Borrar todos los registros movements Borrado selectivo calculated_movements antes del borrado de movementes Borrado selectivo Registros con movimientos con fecha de borrado logico con mas de 31 dias de antiguidad Registros con fecha de borrado logico con mas de 31 dias de antiguidad movements_processed_items Borrar todos los registros processed_items Borrar todos los registros settlement_events Borrado selectivo Registros con fecha de borrado logico borrar todo settlements Borrado selectivo Registros con status cancelados borrar todos tmp_minimos Borrar todos los registros | H14: Gamma | K14: A planificar | AA14: =_xlfn.XLOOKUP(Backlog[[#This Row],[Estado]],CatEstados[Estado],CatEstados[Fase],"Otro") -> Por hacer | AB14: =IF(OR(ISBLANK(Backlog[[#This Row],[Fecha comprometida (para UAT)]]),Backlog[[#This Row],[Fecha comprometida (para UAT)]]=""), "Sin fecha comprometida", IF( Backlog[[#This Row],[Fecha Real de Cierre]]="", TODAY()-Backlog[[#This Row],[Fecha comprometida (para UAT)]], Backlog[[#This Row],[Fecha Real de Cierre]]-Backlog[[#This Row],[Fecha comprometida (para UAT)]] ) ) -> Sin fecha comprometida | AC14: =IF(OR(#REF!="",NOT(ISNUMBER(Backlog[[#This Row],[Dias_abiertos]]))),"",IF(Backlog[[#This Row],[Dias_abiertos]]<=7,"En plazo",IFERROR(IF(Backlog[[#This Row],[Dias_abiertos]]=_xlfn.XLOOKUP(TRIM(#REF!),CatSLA[Prioridad],CatSLA[SLA_dias],""),"En plazo","Fuera de plazo"),"Sin SLA"))) -> #REF!
A15: SF16554 | B15: Mantenimiento correctivo | C15: Muy alta | D15: 46140 | E15: CORR-NOA Error al cargar predistribución | F15: Al intentar cargar el archivo de redistribución se genera un error que deja como pendiente el proceso. Se necesita tener todo cargado los sorteos de mayo a más tardar resuelto el día jueves 30/04. Se adjunta imagen del error | G15: Corrientes | H15: NOA | I15: SAC | K15: A priorizar | O15: NOA tiene que filtrar las concentradoras | S15: 24 | AA15: =_xlfn.XLOOKUP(Backlog[[#This Row],[Estado]],CatEstados[Estado],CatEstados[Fase],"Otro") -> Por hacer | AB15: =IF(OR(ISBLANK(Backlog[[#This Row],[Fecha comprometida (para UAT)]]),Backlog[[#This Row],[Fecha comprometida (para UAT)]]=""), "Sin fecha comprometida", IF( Backlog[[#This Row],[Fecha Real de Cierre]]="", TODAY()-Backlog[[#This Row],[Fecha comprometida (para UAT)]], Backlog[[#This Row],[Fecha Real de Cierre]]-Backlog[[#This Row],[Fecha comprometida (para UAT)]] ) ) -> Sin fecha comprometida | AC15: =IF(OR(#REF!="",NOT(ISNUMBER(Backlog[[#This Row],[Dias_abiertos]]))),"",IF(Backlog[[#This Row],[Dias_abiertos]]<=7,"En plazo",IFERROR(IF(Backlog[[#This Row],[Dias_abiertos]]=_xlfn.XLOOKUP(TRIM(#REF!),CatSLA[Prioridad],CatSLA[SLA_dias],""),"En plazo","Fuera de plazo"),"Sin SLA"))) -> #REF!
A16: GAMMA - 000719 SF16366 | B16: Mantenimiento evolutivo | C16: Alta | D16: 46135 | E16: Adaptar archivo D&B para aceptar múltiples conceptos | F16: En SIGA hoy en dia cargan un archivo apuntado a varios codigos contables | G16: Santiago del Estero | H16: Gamma | I16: Mantenimiento | J16: 1 | K16: En desarrollo | L16: 46142 | O16: Autorizado por la direccción | P16: Desarrollado - Jimena | Q16: Adaptar archivo D&B para aceptar múltiples conceptos - 1.2.pdf | S16: 120 | T16: 9 | AA16: =_xlfn.XLOOKUP(Backlog[[#This Row],[Estado]],CatEstados[Estado],CatEstados[Fase],"Otro") -> En curso | AB16: =IF(OR(ISBLANK(Backlog[[#This Row],[Fecha comprometida (para UAT)]]),Backlog[[#This Row],[Fecha comprometida (para UAT)]]=""), "Sin fecha comprometida", IF( Backlog[[#This Row],[Fecha Real de Cierre]]="", TODAY()-Backlog[[#This Row],[Fecha comprometida (para UAT)]], Backlog[[#This Row],[Fecha Real de Cierre]]-Backlog[[#This Row],[Fecha comprometida (para UAT)]] ) ) -> Sin fecha comprometida | AC16: =IF(OR(#REF!="",NOT(ISNUMBER(Backlog[[#This Row],[Dias_abiertos]]))),"",IF(Backlog[[#This Row],[Dias_abiertos]]<=7,"En plazo",IFERROR(IF(Backlog[[#This Row],[Dias_abiertos]]=_xlfn.XLOOKUP(TRIM(#REF!),CatSLA[Prioridad],CatSLA[SLA_dias],""),"En plazo","Fuera de plazo"),"Sin SLA"))) -> #REF!
A17: GAMMA - 000722 SF16367 | B17: Mantenimiento evolutivo | C17: Alta | D17: 46135 | E17: Adaptar archivo D&B para aceptar operaciones de Embargos y Garantías | F17: En SIGA hoy en dia cargan un archivo donde indican un numero de porcentaje para que el sistema realice un calculo (Garantia, Embargo judicial, etc), a su vez, colocan en el archivo un importe de tope para descuento. GAMMA no acepta este tipo de archivos y no aplica calculos desde d&b. | G17: Santiago del Estero | H17: Gamma | I17: Mantenimiento | J17: 2 | K17: En desarrollo | L17: 46142 | O17: Autorizado por la direccción | P17: Desarrollado - Jimena | Q17: Adaptar archivo D&B para aceptar operaciones de Embargos y Garantías - 1.0.pdf | S17: 160 | T17: 13 | AA17: =_xlfn.XLOOKUP(Backlog[[#This Row],[Estado]],CatEstados[Estado],CatEstados[Fase],"Otro") -> En curso | AB17: =IF(OR(ISBLANK(Backlog[[#This Row],[Fecha comprometida (para UAT)]]),Backlog[[#This Row],[Fecha comprometida (para UAT)]]=""), "Sin fecha comprometida", IF( Backlog[[#This Row],[Fecha Real de Cierre]]="", TODAY()-Backlog[[#This Row],[Fecha comprometida (para UAT)]], Backlog[[#This Row],[Fecha Real de Cierre]]-Backlog[[#This Row],[Fecha comprometida (para UAT)]] ) ) -> Sin fecha comprometida | AC17: =IF(OR(#REF!="",NOT(ISNUMBER(Backlog[[#This Row],[Dias_abiertos]]))),"",IF(Backlog[[#This Row],[Dias_abiertos]]<=7,"En plazo",IFERROR(IF(Backlog[[#This Row],[Dias_abiertos]]=_xlfn.XLOOKUP(TRIM(#REF!),CatSLA[Prioridad],CatSLA[SLA_dias],""),"En plazo","Fuera de plazo"),"Sin SLA"))) -> #REF!
A18: 16608 | B18: Mantenimiento evolutivo | C18: Alta | D18: 46142 | E18: Configuracion particular de vencimientos por PDV | F18: En SIGA tienen configurado para cada agencia un dia de vencimiento en particular, con la particularidad de que cuando llega el dia previo al pago, el pago se saltea a la semana siguiente con el fin de que al PDV le quede, al menos, una recaudacion para su uso. | G18: Santiago del Estero | H18: Gamma | I18: Mantenimiento | J18: 5 | K18: En desarrollo | L18: 46147 | O18: Autorizado por la direccción | P18: Desarrollado - Jimena | Q18: SDE - GAMMA - Configuracion particular de vencimientos por PDV - 1.1.pdf | S18: 136 | T18: 9 | AA18: =_xlfn.XLOOKUP(Backlog[[#This Row],[Estado]],CatEstados[Estado],CatEstados[Fase],"Otro") -> En curso | AB18: =IF(OR(ISBLANK(Backlog[[#This Row],[Fecha comprometida (para UAT)]]),Backlog[[#This Row],[Fecha comprometida (para UAT)]]=""), "Sin fecha comprometida", IF( Backlog[[#This Row],[Fecha Real de Cierre]]="", TODAY()-Backlog[[#This Row],[Fecha comprometida (para UAT)]], Backlog[[#This Row],[Fecha Real de Cierre]]-Backlog[[#This Row],[Fecha comprometida (para UAT)]] ) ) -> Sin fecha comprometida | AC18: =IF(OR(#REF!="",NOT(ISNUMBER(Backlog[[#This Row],[Dias_abiertos]]))),"",IF(Backlog[[#This Row],[Dias_abiertos]]<=7,"En plazo",IFERROR(IF(Backlog[[#This Row],[Dias_abiertos]]=_xlfn.XLOOKUP(TRIM(#REF!),CatSLA[Prioridad],CatSLA[SLA_dias],""),"En plazo","Fuera de plazo"),"Sin SLA"))) -> #REF!
A19: 16609 | B19: Mantenimiento evolutivo | C19: Alta | D19: 46142 | E19: Republicacion de deuda | F19: Al momento de aplicarse el nuevo sistema bancario (2026) la Loteria iniciara a realizar la republicacion de deuda. Hoy en dia en SIGA se encuentra esta opcion disponible generandose un nuevo archivos con dos opciones de habilitarlo: 1) Dia de emision de cta.cte: genera archivo con todas las agencias que no cancelaron el resumen colocandole nueva fecha de vencimiento. 2) Por agencia: Permite seleccionar los resumenes pendientes que se deciden abonar, genera un archivo con la informacion preseleccionada y se le coloca la nueva fecha de vencimiento. | G19: Santiago del Estero | H19: Gamma | I19: Mantenimiento | J19: 6 | K19: A planificar | O19: Autorizado por la direccción | Q19: SDE - GAMMA - Republicación de deuda - 1.0.docx | S19: 160 | AA19: =_xlfn.XLOOKUP(Backlog[[#This Row],[Estado]],CatEstados[Estado],CatEstados[Fase],"Otro") -> Por hacer | AB19: =IF(OR(ISBLANK(Backlog[[#This Row],[Fecha comprometida (para UAT)]]),Backlog[[#This Row],[Fecha comprometida (para UAT)]]=""), "Sin fecha comprometida", IF( Backlog[[#This Row],[Fecha Real de Cierre]]="", TODAY()-Backlog[[#This Row],[Fecha comprometida (para UAT)]], Backlog[[#This Row],[Fecha Real de Cierre]]-Backlog[[#This Row],[Fecha comprometida (para UAT)]] ) ) -> Sin fecha comprometida | AC19: =IF(OR(#REF!="",NOT(ISNUMBER(Backlog[[#This Row],[Dias_abiertos]]))),"",IF(Backlog[[#This Row],[Dias_abiertos]]<=7,"En plazo",IFERROR(IF(Backlog[[#This Row],[Dias_abiertos]]=_xlfn.XLOOKUP(TRIM(#REF!),CatSLA[Prioridad],CatSLA[SLA_dias],""),"En plazo","Fuera de plazo"),"Sin SLA"))) -> #REF!
A20: GAMMA - 000739 16403 | B20: Mantenimiento evolutivo | C20: Alta | D20: 46136 | E20: ID717 - Ampliar funcional de roles y perfiles | F20: En GAMMA actualmente se puede realizar BP desde el modulo "Loteria" y desde el modulo de "Caja" por cualquier usuario con un rol que permita el ingreso a esos modulos. La Loteria solicita que la accion del BP no pueda ser realizada por cualquier usuario, sino por alguien autorizado (rol personalizado) | G20: Santiago del Estero | H20: Gamma | I20: Mantenimiento | J20: 3 | K20: A planificar | O20: Autorizado por la direccción | Q20: ID717 - Gamma - Cambios en los roles actuales - 2.0.docx | S20: 400 | AA20: =_xlfn.XLOOKUP(Backlog[[#This Row],[Estado]],CatEstados[Estado],CatEstados[Fase],"Otro") -> Por hacer | AB20: =IF(OR(ISBLANK(Backlog[[#This Row],[Fecha comprometida (para UAT)]]),Backlog[[#This Row],[Fecha comprometida (para UAT)]]=""), "Sin fecha comprometida", IF( Backlog[[#This Row],[Fecha Real de Cierre]]="", TODAY()-Backlog[[#This Row],[Fecha comprometida (para UAT)]], Backlog[[#This Row],[Fecha Real de Cierre]]-Backlog[[#This Row],[Fecha comprometida (para UAT)]] ) ) -> Sin fecha comprometida | AC20: =IF(OR(#REF!="",NOT(ISNUMBER(Backlog[[#This Row],[Dias_abiertos]]))),"",IF(Backlog[[#This Row],[Dias_abiertos]]<=7,"En plazo",IFERROR(IF(Backlog[[#This Row],[Dias_abiertos]]=_xlfn.XLOOKUP(TRIM(#REF!),CatSLA[Prioridad],CatSLA[SLA_dias],""),"En plazo","Fuera de plazo"),"Sin SLA"))) -> #REF!
A21: GAMMA - 000738 16404 | B21: Mantenimiento evolutivo | C21: Alta | D21: 46136 | E21: Resumen para pago en banco con código de barras | F21: hoy en dia SIGA genera un reporte/listado con los resumenes bancarios a pagar colocandole un talon de pago con codigo de barra, GAMMA genera el reporte SIN el talon de pago. | G21: Santiago del Estero | H21: Gamma | I21: Mantenimiento | J21: 8 | K21: En desarrollo | L21: 46147 | O21: Autorizado por la direccción | P21: Alejandro Falta pruebas unitarias | Q21: SDE - Gamma - Código de barras para el resumen de agentes - 1.1.pdf | S21: 32 | T21: 8 | AA21: =_xlfn.XLOOKUP(Backlog[[#This Row],[Estado]],CatEstados[Estado],CatEstados[Fase],"Otro") -> En curso | AB21: =IF(OR(ISBLANK(Backlog[[#This Row],[Fecha comprometida (para UAT)]]),Backlog[[#This Row],[Fecha comprometida (para UAT)]]=""), "Sin fecha comprometida", IF( Backlog[[#This Row],[Fecha Real de Cierre]]="", TODAY()-Backlog[[#This Row],[Fecha comprometida (para UAT)]], Backlog[[#This Row],[Fecha Real de Cierre]]-Backlog[[#This Row],[Fecha comprometida (para UAT)]] ) ) -> Sin fecha comprometida | AC21: =IF(OR(#REF!="",NOT(ISNUMBER(Backlog[[#This Row],[Dias_abiertos]]))),"",IF(Backlog[[#This Row],[Dias_abiertos]]<=7,"En plazo",IFERROR(IF(Backlog[[#This Row],[Dias_abiertos]]=_xlfn.XLOOKUP(TRIM(#REF!),CatSLA[Prioridad],CatSLA[SLA_dias],""),"En plazo","Fuera de plazo"),"Sin SLA"))) -> #REF!
A22: 16453 | B22: Mantenimiento evolutivo | C22: Alta | D22: 46136 | E22: Adaptar GAMMA para poder liquidar día abierto | F22: GAMMA no está permitiendo liquidar con la config a día abierto >>> DC Probar lunes 15 x la noche (2340hs / 00.05hs) >> Martes evaluar resultados | G22: Santiago del Estero | H22: Gamma | I22: Mantenimiento | J22: 9 | K22: En desarrollo | L22: 46150 | O22: Autorizado por la direccción | P22: Desarrollado - Tejerina | Q22: SDE - GAMMA - Adaptar GAMMA para poder liquidar día abierto - v1.2.pdf | S22: 400 | AA22: =_xlfn.XLOOKUP(Backlog[[#This Row],[Estado]],CatEstados[Estado],CatEstados[Fase],"Otro") -> En curso | AB22: =IF(OR(ISBLANK(Backlog[[#This Row],[Fecha comprometida (para UAT)]]),Backlog[[#This Row],[Fecha comprometida (para UAT)]]=""), "Sin fecha comprometida", IF( Backlog[[#This Row],[Fecha Real de Cierre]]="", TODAY()-Backlog[[#This Row],[Fecha comprometida (para UAT)]], Backlog[[#This Row],[Fecha Real de Cierre]]-Backlog[[#This Row],[Fecha comprometida (para UAT)]] ) ) -> Sin fecha comprometida | AC22: =IF(OR(#REF!="",NOT(ISNUMBER(Backlog[[#This Row],[Dias_abiertos]]))),"",IF(Backlog[[#This Row],[Dias_abiertos]]<=7,"En plazo",IFERROR(IF(Backlog[[#This Row],[Dias_abiertos]]=_xlfn.XLOOKUP(TRIM(#REF!),CatSLA[Prioridad],CatSLA[SLA_dias],""),"En plazo","Fuera de plazo"),"Sin SLA"))) -> #REF!
A23: 16454 | B23: Mantenimiento evolutivo | C23: Alta | D23: 46136 | E23: Buzón para envió de documentación con indicador de lectura (envío masivo de cert de IIBB) | F23: El buzón se encuentra en fase de pruebas QA pero el pedido de la lotería es que se pueda realizar envío masivo de los cert de IIBB | G23: Santiago del Estero | H23: Gamma | I23: Mantenimiento | J23: 48 | K23: En desarrollo | O23: Autorizado por la direccción | P23: Alejandro. Desarrollado. | Q23: Lotemovil – Envío masivo de certificados IIBB con acuse de lectura - 1.2.docx | S23: 100 | AA23: =_xlfn.XLOOKUP(Backlog[[#This Row],[Estado]],CatEstados[Estado],CatEstados[Fase],"Otro") -> En curso | AB23: =IF(OR(ISBLANK(Backlog[[#This Row],[Fecha comprometida (para UAT)]]),Backlog[[#This Row],[Fecha comprometida (para UAT)]]=""), "Sin fecha comprometida", IF( Backlog[[#This Row],[Fecha Real de Cierre]]="", TODAY()-Backlog[[#This Row],[Fecha comprometida (para UAT)]], Backlog[[#This Row],[Fecha Real de Cierre]]-Backlog[[#This Row],[Fecha comprometida (para UAT)]] ) ) -> Sin fecha comprometida | AC23: =IF(OR(#REF!="",NOT(ISNUMBER(Backlog[[#This Row],[Dias_abiertos]]))),"",IF(Backlog[[#This Row],[Dias_abiertos]]<=7,"En plazo",IFERROR(IF(Backlog[[#This Row],[Dias_abiertos]]=_xlfn.XLOOKUP(TRIM(#REF!),CatSLA[Prioridad],CatSLA[SLA_dias],""),"En plazo","Fuera de plazo"),"Sin SLA"))) -> #REF!
A24: 16455 | B24: Mantenimiento evolutivo | C24: Alta | D24: 46137 | E24: Visualizar estado de resúmenes en pantalla | F24: Estado de los resúmenes para que el dueño de agencias pueda ver y controlar | G24: Santiago del Estero | H24: Gamma | I24: Mantenimiento | J24: 49 | K24: En desarrollo | O24: Autorizado por la direccción | P24: Alejandro. Desarrollado. | Q24: https://tecnoaccionsa.sharepoint.com/:w:/s/GAMMA.2024/IQAaIvvg3eg5SJVxUyCXE6IBAc_JlFy7qcMdpOnljAxsJmY?e=ffUJif | S24: 60 | AA24: =_xlfn.XLOOKUP(Backlog[[#This Row],[Estado]],CatEstados[Estado],CatEstados[Fase],"Otro") -> En curso | AB24: =IF(OR(ISBLANK(Backlog[[#This Row],[Fecha comprometida (para UAT)]]),Backlog[[#This Row],[Fecha comprometida (para UAT)]]=""), "Sin fecha comprometida", IF( Backlog[[#This Row],[Fecha Real de Cierre]]="", TODAY()-Backlog[[#This Row],[Fecha comprometida (para UAT)]], Backlog[[#This Row],[Fecha Real de Cierre]]-Backlog[[#This Row],[Fecha comprometida (para UAT)]] ) ) -> Sin fecha comprometida | AC24: =IF(OR(#REF!="",NOT(ISNUMBER(Backlog[[#This Row],[Dias_abiertos]]))),"",IF(Backlog[[#This Row],[Dias_abiertos]]<=7,"En plazo",IFERROR(IF(Backlog[[#This Row],[Dias_abiertos]]=_xlfn.XLOOKUP(TRIM(#REF!),CatSLA[Prioridad],CatSLA[SLA_dias],""),"En plazo","Fuera de plazo"),"Sin SLA"))) -> #REF!
A25: 16456 | B25: Mantenimiento evolutivo | C25: Alta | D25: 46136 | E25: Control y cierre de TJ's - ver cierres m9 y m5 | F25: Control de las operaciones de m9 (se usa para el cierre de sorteo y/o consultas) y m5 (fin de jornada) por TJ | G25: Santiago del Estero | H25: Gamma | I25: Mantenimiento | J25: 50 | K25: En desarrollo | O25: Autorizado por la direccción | P25: Paolo y Marcos en desarrollo | Q25: Lotemovil – Control y cierre de TJ ver cierres M9 y M5 - 1.0.docx | S25: 100 | AA25: =_xlfn.XLOOKUP(Backlog[[#This Row],[Estado]],CatEstados[Estado],CatEstados[Fase],"Otro") -> En curso | AB25: =IF(OR(ISBLANK(Backlog[[#This Row],[Fecha comprometida (para UAT)]]),Backlog[[#This Row],[Fecha comprometida (para UAT)]]=""), "Sin fecha comprometida", IF( Backlog[[#This Row],[Fecha Real de Cierre]]="", TODAY()-Backlog[[#This Row],[Fecha comprometida (para UAT)]], Backlog[[#This Row],[Fecha Real de Cierre]]-Backlog[[#This Row],[Fecha comprometida (para UAT)]] ) ) -> Sin fecha comprometida | AC25: =IF(OR(#REF!="",NOT(ISNUMBER(Backlog[[#This Row],[Dias_abiertos]]))),"",IF(Backlog[[#This Row],[Dias_abiertos]]<=7,"En plazo",IFERROR(IF(Backlog[[#This Row],[Dias_abiertos]]=_xlfn.XLOOKUP(TRIM(#REF!),CatSLA[Prioridad],CatSLA[SLA_dias],""),"En plazo","Fuera de plazo"),"Sin SLA"))) -> #REF!
A26: 16458 | B26: Mantenimiento evolutivo | C26: Alta | D26: 46136 | E26: Control y cierre de TJ's - ver productividad por máquina con apertura igual a la de lotermovil viejo | F26: Control y cierre de TJ's - ver productividad por máquina con apertura igual a la de lotermovil viejo | G26: Santiago del Estero | H26: Gamma | I26: Mantenimiento | J26: 51 | K26: En desarrollo | O26: Autorizado por la direccción | P26: Paolo y Marcos en desarrollo. | Q26: Lotemovil – Control y cierre de TJ ver productividad por terminal - 1.2.docx | S26: 100 | AA26: =_xlfn.XLOOKUP(Backlog[[#This Row],[Estado]],CatEstados[Estado],CatEstados[Fase],"Otro") -> En curso | AB26: =IF(OR(ISBLANK(Backlog[[#This Row],[Fecha comprometida (para UAT)]]),Backlog[[#This Row],[Fecha comprometida (para UAT)]]=""), "Sin fecha comprometida", IF( Backlog[[#This Row],[Fecha Real de Cierre]]="", TODAY()-Backlog[[#This Row],[Fecha comprometida (para UAT)]], Backlog[[#This Row],[Fecha Real de Cierre]]-Backlog[[#This Row],[Fecha comprometida (para UAT)]] ) ) -> Sin fecha comprometida | AC26: =IF(OR(#REF!="",NOT(ISNUMBER(Backlog[[#This Row],[Dias_abiertos]]))),"",IF(Backlog[[#This Row],[Dias_abiertos]]<=7,"En plazo",IFERROR(IF(Backlog[[#This Row],[Dias_abiertos]]=_xlfn.XLOOKUP(TRIM(#REF!),CatSLA[Prioridad],CatSLA[SLA_dias],""),"En plazo","Fuera de plazo"),"Sin SLA"))) -> #REF!
A27: 16667 | B27: Mantenimiento evolutivo | C27: Alta | D27: 46146 | E27: Listado - estado general de resúmenes histórico | F27: Listados/Listados Generales/Contaduría/ Liquidaciones Agentes/Resúmenes para Lotería/estado general de resúmenes histórico | G27: Santiago del Estero | H27: Gamma | I27: Mantenimiento | J27: 13 | K27: A planificar | O27: Autorizado por la direccción | Q27: SDE - GAMMA - Listado - estado general de resúmenes histórico - 1.0.docx | S27: 24 | AA27: =_xlfn.XLOOKUP(Backlog[[#This Row],[Estado]],CatEstados[Estado],CatEstados[Fase],"Otro") -> Por hacer | AB27: =IF(OR(ISBLANK(Backlog[[#This Row],[Fecha comprometida (para UAT)]]),Backlog[[#This Row],[Fecha comprometida (para UAT)]]=""), "Sin fecha comprometida", IF( Backlog[[#This Row],[Fecha Real de Cierre]]="", TODAY()-Backlog[[#This Row],[Fecha comprometida (para UAT)]], Backlog[[#This Row],[Fecha Real de Cierre]]-Backlog[[#This Row],[Fecha comprometida (para UAT)]] ) ) -> Sin fecha comprometida | AC27: =IF(OR(#REF!="",NOT(ISNUMBER(Backlog[[#This Row],[Dias_abiertos]]))),"",IF(Backlog[[#This Row],[Dias_abiertos]]<=7,"En plazo",IFERROR(IF(Backlog[[#This Row],[Dias_abiertos]]=_xlfn.XLOOKUP(TRIM(#REF!),CatSLA[Prioridad],CatSLA[SLA_dias],""),"En plazo","Fuera de plazo"),"Sin SLA"))) -> #REF!
A28: 16410 | B28: Mantenimiento evolutivo | C28: Alta | D28: 46136 | E28: Listado - movimientos por imputación/sorteo/código | F28: Listados/Listados Generales/Contaduría/ Liquidaciones Agentes/Resúmenes para Lotería/movimientos por imputación/sorteo/código | G28: Santiago del Estero | H28: Gamma | I28: Mantenimiento | J28: 16 | K28: A planificar | O28: Autorizado por la direccción | Q28: SDE - GAMMA - Listado - Movimientos por imputación-sorteo-codigo - 1.0.docx | S28: 24 | AA28: =_xlfn.XLOOKUP(Backlog[[#This Row],[Estado]],CatEstados[Estado],CatEstados[Fase],"Otro") -> Por hacer | AB28: =IF(OR(ISBLANK(Backlog[[#This Row],[Fecha comprometida (para UAT)]]),Backlog[[#This Row],[Fecha comprometida (para UAT)]]=""), "Sin fecha comprometida", IF( Backlog[[#This Row],[Fecha Real de Cierre]]="", TODAY()-Backlog[[#This Row],[Fecha comprometida (para UAT)]], Backlog[[#This Row],[Fecha Real de Cierre]]-Backlog[[#This Row],[Fecha comprometida (para UAT)]] ) ) -> Sin fecha comprometida | AC28: =IF(OR(#REF!="",NOT(ISNUMBER(Backlog[[#This Row],[Dias_abiertos]]))),"",IF(Backlog[[#This Row],[Dias_abiertos]]<=7,"En plazo",IFERROR(IF(Backlog[[#This Row],[Dias_abiertos]]=_xlfn.XLOOKUP(TRIM(#REF!),CatSLA[Prioridad],CatSLA[SLA_dias],""),"En plazo","Fuera de plazo"),"Sin SLA"))) -> #REF!
A29: 16668 | B29: Mantenimiento evolutivo | C29: Alta | D29: 46146 | E29: Listado - Crédito autorizados por sucursal | F29: Listados/Listados Generales/Contaduría/Bancos/Crédito autorizados por sucursal | G29: Santiago del Estero | H29: Gamma | I29: Mantenimiento | J29: 19 | K29: A planificar | O29: Autorizado por la direccción | Q29: SDE - GAMMA - Listados - Creditos Autorizados por Sucursal - 1.0.docx | S29: 24 | AA29: =_xlfn.XLOOKUP(Backlog[[#This Row],[Estado]],CatEstados[Estado],CatEstados[Fase],"Otro") -> Por hacer | AB29: =IF(OR(ISBLANK(Backlog[[#This Row],[Fecha comprometida (para UAT)]]),Backlog[[#This Row],[Fecha comprometida (para UAT)]]=""), "Sin fecha comprometida", IF( Backlog[[#This Row],[Fecha Real de Cierre]]="", TODAY()-Backlog[[#This Row],[Fecha comprometida (para UAT)]], Backlog[[#This Row],[Fecha Real de Cierre]]-Backlog[[#This Row],[Fecha comprometida (para UAT)]] ) ) -> Sin fecha comprometida | AC29: =IF(OR(#REF!="",NOT(ISNUMBER(Backlog[[#This Row],[Dias_abiertos]]))),"",IF(Backlog[[#This Row],[Dias_abiertos]]<=7,"En plazo",IFERROR(IF(Backlog[[#This Row],[Dias_abiertos]]=_xlfn.XLOOKUP(TRIM(#REF!),CatSLA[Prioridad],CatSLA[SLA_dias],""),"En plazo","Fuera de plazo"),"Sin SLA"))) -> #REF!
A30: 16670 | B30: Mantenimiento evolutivo | C30: Alta | D30: 46146 | E30: Listado - Débitos autorizados por sucursal | F30: Listados/Listados Generales/Contaduría/Bancos/Débitos autorizados por sucursal | G30: Santiago del Estero | H30: Gamma | I30: Mantenimiento | J30: 22 | K30: A planificar | O30: Autorizado por la direccción | Q30: SDE - GAMMA - Listados - Debitos Autorizados por Sucursal - 1.0.docx | S30: 24 | AA30: =_xlfn.XLOOKUP(Backlog[[#This Row],[Estado]],CatEstados[Estado],CatEstados[Fase],"Otro") -> Por hacer | AB30: =IF(OR(ISBLANK(Backlog[[#This Row],[Fecha comprometida (para UAT)]]),Backlog[[#This Row],[Fecha comprometida (para UAT)]]=""), "Sin fecha comprometida", IF( Backlog[[#This Row],[Fecha Real de Cierre]]="", TODAY()-Backlog[[#This Row],[Fecha comprometida (para UAT)]], Backlog[[#This Row],[Fecha Real de Cierre]]-Backlog[[#This Row],[Fecha comprometida (para UAT)]] ) ) -> Sin fecha comprometida | AC30: =IF(OR(#REF!="",NOT(ISNUMBER(Backlog[[#This Row],[Dias_abiertos]]))),"",IF(Backlog[[#This Row],[Dias_abiertos]]<=7,"En plazo",IFERROR(IF(Backlog[[#This Row],[Dias_abiertos]]=_xlfn.XLOOKUP(TRIM(#REF!),CatSLA[Prioridad],CatSLA[SLA_dias],""),"En plazo","Fuera de plazo"),"Sin SLA"))) -> #REF!
A31: 16671 | B31: Mantenimiento evolutivo | C31: Alta | D31: 46146 | E31: Listado - Liquidación | F31: Listados/Listados Generales/Contaduría/Bancos/Liquidación | G31: Santiago del Estero | H31: Gamma | I31: Mantenimiento | J31: 23 | K31: A planificar | O31: autorizado por la direccción | S31: 24 | AA31: =_xlfn.XLOOKUP(Backlog[[#This Row],[Estado]],CatEstados[Estado],CatEstados[Fase],"Otro") -> Por hacer | AB31: =IF(OR(ISBLANK(Backlog[[#This Row],[Fecha comprometida (para UAT)]]),Backlog[[#This Row],[Fecha comprometida (para UAT)]]=""), "Sin fecha comprometida", IF( Backlog[[#This Row],[Fecha Real de Cierre]]="", TODAY()-Backlog[[#This Row],[Fecha comprometida (para UAT)]], Backlog[[#This Row],[Fecha Real de Cierre]]-Backlog[[#This Row],[Fecha comprometida (para UAT)]] ) ) -> Sin fecha comprometida | AC31: =IF(OR(#REF!="",NOT(ISNUMBER(Backlog[[#This Row],[Dias_abiertos]]))),"",IF(Backlog[[#This Row],[Dias_abiertos]]<=7,"En plazo",IFERROR(IF(Backlog[[#This Row],[Dias_abiertos]]=_xlfn.XLOOKUP(TRIM(#REF!),CatSLA[Prioridad],CatSLA[SLA_dias],""),"En plazo","Fuera de plazo"),"Sin SLA"))) -> #REF!
A32: 16452 | B32: Mantenimiento evolutivo | C32: Alta | D32: 46136 | E32: Listado - certificado Retenciones IB | F32: Listados/Listados Generales/Contaduría/Impuestos/Rentas/certificado Retenciones IB (Se envia a las agencias a través del panel de agentes) | G32: Santiago del Estero | H32: Gamma | I32: Mantenimiento | J32: 26 | K32: A planificar | O32: autorizado por la direccción | Q32: SDE - GAMMA - Certificado Retenciones IIBB - 1.0.docx | S32: 24 | AA32: =_xlfn.XLOOKUP(Backlog[[#This Row],[Estado]],CatEstados[Estado],CatEstados[Fase],"Otro") -> Por hacer | AB32: =IF(OR(ISBLANK(Backlog[[#This Row],[Fecha comprometida (para UAT)]]),Backlog[[#This Row],[Fecha comprometida (para UAT)]]=""), "Sin fecha comprometida", IF( Backlog[[#This Row],[Fecha Real de Cierre]]="", TODAY()-Backlog[[#This Row],[Fecha comprometida (para UAT)]], Backlog[[#This Row],[Fecha Real de Cierre]]-Backlog[[#This Row],[Fecha comprometida (para UAT)]] ) ) -> Sin fecha comprometida | AC32: =IF(OR(#REF!="",NOT(ISNUMBER(Backlog[[#This Row],[Dias_abiertos]]))),"",IF(Backlog[[#This Row],[Dias_abiertos]]<=7,"En plazo",IFERROR(IF(Backlog[[#This Row],[Dias_abiertos]]=_xlfn.XLOOKUP(TRIM(#REF!),CatSLA[Prioridad],CatSLA[SLA_dias],""),"En plazo","Fuera de plazo"),"Sin SLA"))) -> #REF!
